Workbook
Name IQ_CH: 110000
Name IQ_CQ: 5000
Name IQ_CY: 10000
Name IQ_DAILY: 500000
Name IQ_FH: 100000
Name IQ_FQ: 500
Name IQ_FY: 1000
Name IQ_LTM: 2000
Name IQ_MONTH: 15000
Name IQ_NTM: 6000
Name IQ_WEEK: 50000
Name IQ_YTD: 3000

Sheet Input Sheet
B4: Please provide the below inputs
B6: Name of the Company | C6: Bluestar Ltd
B8: WACC Inputs
B9: Country | C9: India
B10: Local Currency 10Y Government Bond Yield | C10: 0.0686
B11: =C9&"'s"&" Moody's Sovereign Rating" -> India's Moody's Sovereign Rating | C11: =VLOOKUP(C9,'Damodaran Data'!B3:D159,3,FALSE) -> Baa3
B12: Credit Default Spread as per Damodaran | C12: =VLOOKUP(C9,'Damodaran Data'!B3:E159,4,FALSE) -> 0.0209
B13: Implied US Equity Risk Premium | C13: 0.0418
B14: Asset Beta | C14: 0.4
B15: Asset Beta Variation (+/-) | C15: 0.05
B16: Debt to Equity Ratio | C16: ='Assumptions Working'!M945 -> 0.18266543
B17: Debt to Capital (Gearing) | C17: ='Assumptions Working'!M946 -> 0.15445233
B18: Marginal Tax Rate | C18: 0.2512
B19: Company Credit Rating Available | C19: Yes
B20: Company is large or small firm? | C20: L | E20: L | F20: Yes
B21: Provide Credit Rating | C21: Aaa/AAA | E21: S | F21: No
B22: Interest Coverage Ratio | C22: ='Ratio Analysis'!G87 -> 10.418769
B23: ICR Based Corporate Default Spread | C23: =IF(C20="L",VLOOKUP(C22,'Damodaran Data'!G4:J19,4,TRUE),VLOOKUP('Input Sheet'!C22,'Damodaran Data'!L4:O19,4,TRUE)) -> 0.004
B24: Small Size Premium | C24: ='WACC Analysis'!D13 -> 0.076
B25: Asset Specific Risk Premium | C25: 0

Sheet Damodaran Data
B1: Country Data | G1: Company Data
B2: Country | C2: Africa | D2: Moody's rating | E2: Rating-based Default Spread | G2: For large non-financial service firms | M2: For smaller and riskier firms
B3: India | C3: Asia | D3: Baa3 | E3: 0.0209 | H3: If interest coverage ratio is | M3: If interest coverage ratio is
B4: United Kingdom | C4: Western Europe | D4: Aa3 | E4: 0.0057 | G4: > | H4: ≤ to | I4: Rating is | J4: Spread is | L4: greater than | M4: ≤ to | N4: Rating is | O4: Spread is
B5: United States | C5: North America | D5: Aa1 | E5: 0.0026 | G5: -100000 | H5: 0.199999 | I5: D2/D | J5: 0.19 | L5: -100000 | M5: 0.499999 | N5: D2/D | O5: 0.19
B6: Abu Dhabi | C6: Middle East | D6: Aa2 | E6: 0.0047 | G6: 0.2 | H6: 0.649999 | I6: C2/C | J6: 0.16 | L6: 0.5 | M6: 0.799999 | N6: C2/C | O6: 0.16
B7: Albania | C7: Eastern Europe & Russia | D7: Ba3 | E7: 0.0342 | G7: 0.65 | H7: 0.799999 | I7: Ca2/CC | J7: 0.1261 | L7: 0.8 | M7: 1.249999 | N7: Ca2/CC | O7: 0.1261
B8: Andorra (Principality of) | C8: Western Europe | D8: Baa1 | E8: 0.0152 | G8: 0.8 | H8: 1.249999 | I8: Caa/CCC | J8: 0.0885 | L8: 1.25 | M8: 1.499999 | N8: Caa/CCC | O8: 0.0885
B9: Angola | C9: Africa | D9: B3 | E9: 0.0618 | G9: 1.25 | H9: 1.499999 | I9: B3/B- | J9: 0.0509 | L9: 1.5 | M9: 1.999999 | N9: B3/B- | O9: 0.0509
B10: Argentina | C10: Central and South America | D10: Caa1 | E10: 0.0714 | G10: 1.5 | H10: 1.749999 | I10: B2/B | J10: 0.0321 | L10: 2 | M10: 2.499999 | N10: B2/B | O10: 0.0321
B11: Armenia | C11: Eastern Europe & Russia | D11: Ba3 | E11: 0.0342 | G11: 1.75 | H11: 1.999999 | I11: B1/B+ | J11: 0.0275 | L11: 2.5 | M11: 2.999999 | N11: B1/B+ | O11: 0.0275
B12: Aruba | C12: Caribbean | D12: Baa3 | E12: 0.0209 | G12: 2 | H12: 2.2499999 | I12: Ba2/BB | J12: 0.0184 | L12: 3 | M12: 3.499999 | N12: Ba2/BB | O12: 0.0184
B13: Australia | C13: Australia & New Zealand | D13: Aaa | E13: 0 | G13: 2.25 | H13: 2.49999 | I13: Ba1/BB+ | J13: 0.0138 | L13: 3.5 | M13: 3.9999999 | N13: Ba1/BB+ | O13: 0.0138
B14: Austria | C14: Western Europe | D14: Aa1 | E14: 0.0026 | G14: 2.5 | H14: 2.999999 | I14: Baa2/BBB | J14: 0.0111 | L14: 4 | M14: 4.499999 | N14: Baa2/BBB | O14: 0.0111
B15: Azerbaijan | C15: Eastern Europe & Russia | D15: Baa3 | E15: 0.0209 | G15: 3 | H15: 4.249999 | I15: A3/A- | J15: 0.0089 | L15: 4.5 | M15: 5.999999 | N15: A3/A- | O15: 0.0089
B16: Bahamas | C16: Caribbean | D16: B1 | E16: 0.0428 | G16: 4.25 | H16: 5.499999 | I16: A2/A | J16: 0.0078 | L16: 6 | M16: 7.499999 | N16: A2/A | O16: 0.0078
... B19: Barbados | C19: Caribbean | D19: B2 | E19: 0.0523 | G19: 8.5 | H19: 100000 | I19: Aaa/AAA | J19: 0.004 | L19: 12.5 | M19: 100000 | N19: Aaa/AAA | O19: 0.004
B20: Belarus | C20: Eastern Europe & Russia | D20: C | E20: 0.175
B21: Belgium | C21: Western Europe | D21: Aa3 | E21: 0.0057
B22: Belize | C22: Central and South America | D22: Caa1 | E22: 0.0714
B23: Benin | C23: Africa | D23: B1 | E23: 0.0428
B24: Bermuda | C24: Caribbean | D24: A2 | E24: 0.0081
B25: Bolivia | C25: Central and South America | D25: Caa3 | E25: 0.0952
B26: Bosnia and Herzegovina | C26: Eastern Europe & Russia | D26: B3 | E26: 0.0618
B27: Botswana | C27: Africa | D27: Baa1 | E27: 0.0152
B28: Brazil | C28: Central and South America | D28: Ba1 | E28: 0.0238
B29: Bulgaria | C29: Eastern Europe & Russia | D29: Baa1 | E29: 0.0152
B30: Burkina Faso | C30: Africa | D30: Caa1 | E30: 0.0714
B31: Cambodia | C31: Asia | D31: B2 | E31: 0.0523
... B159: Zambia | C159: Africa | D159: Caa2 | E159: 0.0857

Sheet Historical Data
B2: HISTORICAL FINANCIAL DATA
B3: All figures in INR Crores.
B5: Fiscal Year Ending | C5: 2017 | D5: =C5+1 -> 2018 | E5: =D5+1 -> 2019 | F5: =E5+1 -> 2020 | G5: =F5+1 -> 2021 | H5: =G5+1 -> 2022 | I5: =H5+1 -> 2023 | J5: =I5+1 -> 2024 | K5: =J5+1 -> 2025 | L5: =K5+1 -> 2026
B7: INCOME STATEMENT
B8: Revenue From Operations | C8: 4385.24 | D8: 4638.95 | E8: 5234.84 | F8: 5360.19 | G8: 4263.59 | H8: 6045.58 | I8: 7977.32 | J8: 9685.36 | K8: 11967.65 | L8: 12401.99
B9: Revenue Growth % | C9: - | D9: =D8/C8-1 -> 0.057855442 | E9: =E8/D8-1 -> 0.12845364 | F9: =F8/E8-1 -> 0.023945335 | G9: =G8/F8-1 -> -0.2045823 | H9: =H8/G8-1 -> 0.41795529 | I9: =I8/H8-1 -> 0.31952931 | J9: =J8/I8-1 -> 0.21411201 | K9: =K8/J8-1 -> 0.23564328 | L9: =L8/K8-1 -> 0.036292839
B10: Less: Cost of Goods Sold/ Services | C10: 3112.25 | D10: 3454.95 | E10: 3931.18 | F10: 4018.11 | G10: 3271.35 | H10: 4714.68 | I10: 6181.67 | J10: 7391.97 | K10: 9074.34 | L10: 9542.09
B11: Gross Profit | C11: =C8-C10 -> 1272.99 | D11: =D8-D10 -> 1184 | E11: =E8-E10 -> 1303.66 | F11: =F8-F10 -> 1342.08 | G11: =G8-G10 -> 992.24 | H11: =H8-H10 -> 1330.9 | I11: =I8-I10 -> 1795.65 | J11: =J8-J10 -> 2293.39 | ... L11: =L8-L10 -> 2859.9
B12: Gross Margin (%) | C12: =C11/C8 -> 0.2902897 | D12: =D11/D8 -> 0.25523017 | E12: =E11/E8 -> 0.24903531 | F12: =F11/F8 -> 0.25037918 | G12: =G11/G8 -> 0.23272407 | H12: =H11/H8 -> 0.2201443 | I12: =I11/I8 -> 0.22509439 | J12: =J11/J8 -> 0.23678934 | ... L12: =L11/L8 -> 0.23060009
B14: Less: SG&A Expenses | C14: 1050.58 | D14: 918.1 | E14: 957.12 | F14: 1059.3 | G14: 752.43 | H14: 984.43 | I14: 1302.87 | J14: 1628.45 | K14: 2017.39 | L14: 1929.5
B15: SG&A % Revenue | C15: =C14/C8 -> 0.23957184 | D15: =D14/D8 -> 0.19791117 | E15: =E14/E8 -> 0.18283653 | F15: =F14/F8 -> 0.19762359 | G15: =G14/G8 -> 0.17647804 | H15: =H14/H8 -> 0.16283467 | I15: =I14/I8 -> 0.16332177 | J15: =J14/J8 -> 0.16813521 | ... L15: =L14/L8 -> 0.15557987
B16: Earning before Interest Taxes Depreciation & Amortization (EBITDA) | C16: =C11-C14 -> 222.41 | D16: =D11-D14 -> 265.9 | E16: =E11-E14 -> 346.54 | F16: =F11-F14 -> 282.78 | G16: =G11-G14 -> 239.81 | H16: =H11-H14 -> 346.47 | I16: =I11-I14 -> 492.78 | J16: =J11-J14 -> 664.94 | ... L16: =L11-L14 -> 930.4
B17: EBITDA Margin (%) | C17: =C16/C8 -> 0.050717863 | D17: =D16/D8 -> 0.057319005 | E17: =E16/E8 -> 0.066198776 | F17: =F16/F8 -> 0.052755593 | G17: =G16/G8 -> 0.056246027 | H17: =H16/H8 -> 0.057309638 | I17: =I16/I8 -> 0.061772625 | J17: =J16/J8 -> 0.068654134 | ... L17: =L16/L8 -> 0.075020219
B19: Less: Depreciation and Amortization | C19: 60.58 | D19: 63.81 | E19: 74.9 | F19: 87.99 | G19: 92.29 | H19: 85.98 | I19: 84.78 | J19: 97.61 | K19: 128.37 | L19: 178.79
B20: Earning before Interest & Taxes (EBIT) | C20: =C16-C19 -> 161.83 | D20: =D16-D19 -> 202.09 | E20: =E16-E19 -> 271.64 | F20: =F16-F19 -> 194.79 | G20: =G16-G19 -> 147.52 | H20: =H16-H19 -> 260.49 | I20: =I16-I19 -> 408 | J20: =J16-J19 -> 567.33 | ... L20: =L16-L19 -> 751.61
B21: EBIT Margin (%) | C21: =C20/C8 -> 0.036903339 | D21: =D20/D8 -> 0.043563737 | E21: =E20/E8 -> 0.051890793 | F21: =F20/F8 -> 0.03634013 | G21: =G20/G8 -> 0.03459995 | H21: =H20/H8 -> 0.043087677 | I21: =I20/I8 -> 0.051144996 | J21: =J20/J8 -> 0.058576036 | ... L21: =L20/L8 -> 0.060603984
B23: Other Income | C23: 13.07 | D23: 16.95 | E23: 24.69 | F23: 44.7 | G23: 62.35 | H23: 35.72 | I23: 30.87 | J23: 47.42 | K23: 75 | L23: 61.91
B24: Less: Interest Expenses | C24: 16.27 | D24: 28.74 | E24: 47.87 | F24: 29.47 | G24: 64.72 | H24: 46.4 | I24: 54.7 | J24: 58.08 | K24: 48.8 | L24: 72.14
B25: Less: Other Expense | C25: 0 | D25: -5.27 | E25: -2.68 | F25: 4.03 | G25: 0 | H25: 0 | I25: -170.81 | J25: 0 | K25: -12.51 | L25: 38.83
B26: Earnings Before Tax (PBT) | C26: =C20+C23-C24-C25 -> 158.63 | D26: =D20+D23-D24-D25 -> 195.57 | E26: =E20+E23-E24-E25 -> 251.14 | F26: =F20+F23-F24-F25 -> 205.99 | G26: =G20+G23-G24-G25 -> 145.15 | H26: =H20+H23-H24-H25 -> 249.81 | I26: =I20+I23-I24-I25 -> 554.98 | J26: =J20+J23-J24-J25 -> 556.67 | ... L26: =L20+L23-L24-L25 -> 702.55
B27: EBT Margins | C27: =C26/C8 -> 0.036173619 | D27: =D26/D8 -> 0.042158247 | E27: =E26/E8 -> 0.047974723 | F27: =F26/F8 -> 0.038429608 | G27: =G26/G8 -> 0.03404408 | H27: =H26/H8 -> 0.041321097 | I27: =I26/I8 -> 0.06956973 | J27: =J26/J8 -> 0.057475406 | ... L27: =L26/L8 -> 0.056648167
B29: Less: Tax Expense | C29: 36.67 | D29: 49.42 | E29: 41.99 | F29: 65.32 | G29: 47.09 | H29: 82.9 | I29: 154.69 | J29: 142.85 | K29: 193.65 | L29: 175.78
B30: Net Income | C30: =C26-C29 -> 121.96 | D30: =D26-D29 -> 146.15 | E30: =E26-E29 -> 209.15 | F30: =F26-F29 -> 140.67 | G30: =G26-G29 -> 98.06 | H30: =H26-H29 -> 166.91 | I30: =I26-I29 -> 400.29 | J30: =J26-J29 -> 413.82 | ... L30: =L26-L29 -> 526.77
B31: Net Income Margin (%) | C31: =C30/C8 -> 0.027811477 | D31: =D30/D8 -> 0.031504974 | E31: =E30/E8 -> 0.039953466 | F31: =F30/F8 -> 0.026243473 | G31: =G30/G8 -> 0.022999397 | H31: =H30/H8 -> 0.0276086 | I31: =I30/I8 -> 0.050178506 | J31: =J30/J8 -> 0.042726342 | ... L31: =L30/L8 -> 0.042474635
B32: Add:Profit from Discontinued Operations | C32: 0 | D32: 0 | E32: 0 | F32: 0 | G32: 0 | H32: 0 | I32: 0 | J32: 0 | K32: 0 | L32: 0
B33: Less: Loss from Discontinued Operations | C33: 0 | D33: 0 | E33: 0 | F33: 0 | G33: 0 | H33: 0 | I33: 0 | J33: 0 | K33: 0 | L33: 0
B34: Net Income of the Year | C34: =C30+C32-C33 -> 121.96 | D34: =D30+D32-D33 -> 146.15 | E34: =E30+E32-E33 -> 209.15 | F34: =F30+F32-F33 -> 140.67 | G34: =G30+G32-G33 -> 98.06 | H34: =H30+H32-H33 -> 166.91 | I34: =I30+I32-I33 -> 400.29 | J34: =J30+J32-J33 -> 413.82 | ... L34: =L30+L32-L33 -> 526.77
B39: BALANCE SHEET
B40: Equity and Liablities
B41: Shareholder's Funds
B42: Equity Share Capital | C42: 19.11 | D42: 19.2 | E42: 19.26 | F42: 19.26 | G42: 19.26 | H42: 19.26 | I42: 19.26 | J42: 41.12 | K42: 41.12 | L42: 41.12
B43: Reserves & Surplus | C43: 738.02 | D43: 773.53 | E43: 853.8 | F43: 763.11 | G43: 865.92 | H43: 998.32 | I43: 1311.39 | J43: 2568.95 | K43: 3023.9 | L43: 3390.29
B44: Total Shareholder's Funds | C44: =SUM(C42:C43) -> 757.13 | D44: =SUM(D42:D43) -> 792.73 | E44: =SUM(E42:E43) -> 873.06 | F44: =SUM(F42:F43) -> 782.37 | G44: =SUM(G42:G43) -> 885.18 | H44: =SUM(H42:H43) -> 1017.58 | I44: =SUM(I42:I43) -> 1330.65 | J44: =SUM(J42:J43) -> 2610.07 | ... L44: =SUM(L42:L43) -> 3431.41
B45: Minority Interest | C45: 1.22 | D45: 1.52 | E45: 1.83 | F45: 2.31 | G45: 2.68 | H45: 2.96 | I45: 3.19 | J45: 2.55 | K45: 2.6 | L45: 2.45
B47: Non Current Liablities
B48: Long Term Borrowings | C48: 20.2 | D48: 25.9 | E48: 8.65 | F48: 47.71 | G48: 349.26 | H48: 241.57 | I48: 161.74 | J48: 0 | K48: 0 | L48: 0
B49: Deferred Tax Liabilities | C49: 0 | D49: 0 | E49: 0 | F49: 0 | G49: 0 | H49: 0 | I49: 0 | J49: 6.98 | K49: 13.45 | L49: 31.6
B50: Other Long Term Liabilities | C50: 4.08 | D50: 6.27 | E50: 6.45 | F50: 47.92 | G50: 40.06 | H50: 71.27 | I50: 108.32 | J50: 103.1 | K50: 206.73 | L50: 191.49
B51: Long Term Provisions | C51: 11.17 | D51: 12.54 | E51: 12.06 | F51: 13.26 | G51: 10.82 | H51: 10.06 | I51: 11.41 | J51: 15.93 | K51: 25.31 | L51: 52.77
B52: Total Non-Current Liabilities | C52: =SUM(C48:C51) -> 35.45 | D52: =SUM(D48:D51) -> 44.71 | E52: =SUM(E48:E51) -> 27.16 | F52: =SUM(F48:F51) -> 108.89 | G52: =SUM(G48:G51) -> 400.14 | H52: =SUM(H48:H51) -> 322.9 | I52: =SUM(I48:I51) -> 281.47 | J52: =SUM(J48:J51) -> 126.01 | ... L52: =SUM(L48:L51) -> 275.86
...

Sheet Growth Drivers
B2: Blue Star Ltd - Growth Drivers
A4: 1 | B4: Rapid housing sector expansion
A5: 2 | B5: accelerated adoption of renewable energy
A6: 3 | B6: vibrant rural economic growth
A7: 4 | B7: Robust demand in Overall Air Conditioning products
A8: 5 | B8: Strong execution in ElectroMechanical Projects
A9: 6 | B9: Demand for Commercial Refrigeration products due to rising healthcare and Food & Beverages sector
A10: 7 | B10: Rapid urbanisation and rising disposable income
A11: 8 | B11: India's becoming manufacturing hub to build domestic supply chains and export growth
A12: 9 | B12: Rising Disposable Income and Consumption
B16: Year | C16: Housing Units Sold
B17: 2022 | C17: 420554
B18: 2023 | C18: 484330
B19: 2024 | C19: 513811
B20: 2025 | C20: 494154
B24: https://www.credaincr.org/iismgmt/all-images/policypdf/pdf_1753099631.pdf
B27: Year | C27: Energy Capacity (MW)
B28: 2015 | C28: 4100.5
B29: 2016 | C29: 7141.3
B30: 2017 | C30: 11466.81
B31: 2018 | C31: 12093.24
B32: 2019 | C32: 8760.56
B33: 2020 | C33: 8843.31
B34: 2021 | C34: 7548.11
B35: 2022 | C35: 14081.97
B36: 2023 | C36: 15274.43
B37: 2024 | C37: 18484.68
B38: 2025 | C38: 28723.65
B42: https://mnre.gov.in/en/year-wise-achievement
B45: Year | C45: Acs unit sold (mn)
B46: 2023 | C46: 10.2
B47: 2024 | C47: 13.3
B48: 2025 | C48: 15.4
B49: 2026 | C49: 14.75

Sheet Assumptions Working
A2: # | B2: Revenue Growth
B4: Segment Mix | E4: FY26 Contribution | G4: Segment Revenue FY26
B6: Electro-Mechanical Projects and Commercial Air Conditioning Systems | E6: =G6/$G$9 -> 0.54529915 | G6: 6762.8
B7: Unitary Products | E7: =G7/$G$9 -> 0.42996291 | G7: 5332.4
B8: Professional Electronics and Industrial Systems | E8: =G8/$G$9 -> 0.024737945 | G8: 306.8
G9: =SUM(G6:G8) -> 12402
A13: # | B13: Company Historical Growth
O14: CAGR
B15: Particulars | D15: 2017 | E15: =D15+1 -> 2018 | F15: =E15+1 -> 2019 | G15: =F15+1 -> 2020 | H15: =G15+1 -> 2021 | I15: =H15+1 -> 2022 | J15: =I15+1 -> 2023 | K15: =J15+1 -> 2024 | L15: =K15+1 -> 2025 | M15: =L15+1 -> 2026 | O15: 3 Years | P15: 5 Years | Q15: 7 Years
B16: Revenue From Operations | D16: ='Historical Data'!C8 -> 4385.24 | E16: ='Historical Data'!D8 -> 4638.95 | F16: ='Historical Data'!E8 -> 5234.84 | G16: ='Historical Data'!F8 -> 5360.19 | H16: ='Historical Data'!G8 -> 4263.59 | I16: ='Historical Data'!H8 -> 6045.58 | J16: ='Historical Data'!I8 -> 7977.32 | K16: ='Historical Data'!J8 -> 9685.36 | ... M16: ='Historical Data'!L8 -> 12401.99 | O16: =_xlfn.RRI(3,J16,M16) -> 0.15845221 | P16: =_xlfn.RRI(5,H16,M16) -> 0.23806426 | Q16: =_xlfn.RRI(7,F16,M16) -> 0.13113012
B17: Growth YoY % | E17: ='Historical Data'!D9 -> 0.057855442 | F17: ='Historical Data'!E9 -> 0.12845364 | G17: ='Historical Data'!F9 -> 0.023945335 | H17: ='Historical Data'!G9 -> -0.2045823 | I17: ='Historical Data'!H9 -> 0.41795529 | J17: ='Historical Data'!I9 -> 0.31952931 | K17: ='Historical Data'!J9 -> 0.21411201 | L17: ='Historical Data'!K9 -> 0.23564328 | M17: ='Historical Data'!L9 -> 0.036292839
B20: Statista | D20: https://www.statista.com/outlook/cmo/household-appliances/major-appliances/air-conditioners/india/?srsltid=AfmBOop31nu0pkk5kCV8MoPgmKk2VtWrxiPHXx6y8TaZqeB64e0d7tMk#revenue
B22: 2023 Revenue | D22: US$9.01bn
B23: CAGR Growth 2026-2031 | D23: 0.1462
B24: Volume Growth in 2027 | D24: 0.1436
M29: REVENUE CHART AND VOLUME CHART
B30: Global Data | D30: https://www.globaldata.com/store/report/india-conditioner-market-analysis/#TabReport_2 | M30: price per unit chart
B32: Conditioner market in India registered a positive compound annual growth rate (CAGR) of 7.21% during the period 2018 to 2023..
B33: The market achieved its strongest performance in 2019, when it grew by 9.46% over its previous year and its weakest performance in 2020, when it increased by 3.76% over 2019.
B35: Imarc Group | D35: https://www.imarcgroup.com/india-air-conditioning-market
B37: The India air conditioning market size was valued at USD 6.15 Billion in 2025 and is projected to reach USD 21.59 Billion by 2034, growing at a CAGR of 14.98% during 2026-2034.
B39: IBEF | D39: https://www.ibef.org/news/indian-room-air-conditioner-market-to-reach-us-5-6-billion-rs-50-000-crore-by-fy29-voltas
B41: The India room air-conditioners (RAC) market is projected to grow at a robust CAGR of 12% and reach US$ 5.6 billion (Rs. 50,000 crore) by FY 2028-29,
B43: ICRA | D43: https://www.icra.in
B45: The long-term demand outlook for the RAC industry, however, remains healthy with a forecasted compounded annual growth rate (CAGR) of 10–15% in volumes between FY2026 and FY2030
B46: Reduction in the goods & services tax (GST) rate on RACs (under 2 tonne) to 18% with effect from September 22, 2025, against 28% earlier, is likely to reduce the prices of RACs by around 6-8%, or around Rs. 2000-3000 per unit, thus boosting demand | D46: PDF
B47: commodity exchange forward contracts | D47: 2
B48: ICRA projects the sales volume for the Indian RAC industry to contract to approximately11.0–11.5 million units in FY2026 from 12.5-13.0 million units in FY2025, primarily due tothe unseasonal rainfall during the summer, which impacted demand in Q1 FY2026
B49: The domestic RAC industry is estimated to have experienced a15-20% YoY decline in volumes during April–July 2025.
B50: This compressed RAC volumes in 4M FY2026 by around 15-20% in YoY terms, which will, however, be partly compensated by sales during the rest of the year due to favorable summer expectations in the Western and Sothern regions during H2 FY2026.
B51: India’s domestic RAC manufacturing capacity, currently at24–26 million units annually, is projected to grow to30–32 million units by CY2027and40–42 million units by CY2030, reflecting a40–50% increase,to meet rising demand.
B54: SOIC | D54: https://www.soic.in/blog-page/from-heatwaves-to-market-waves-decoding-indias-ac-industry
B56: Current penetration: Just 8% in India (vs 60–100% in developed markets).
B57: Market growth: Indian RAC (Room Air Conditioner) volumes grew at a 10% CAGR (FY13–19), and post-COVID, the momentum picked up with a projected 17% CAGR from FY23–28
B58: Global vs India gap: Global AC volumes ~150 mn units, China ~85 mn, India just ~7–8 mn (Exhibit 10). The runway is massive.
B59: India’s current penetration ~8% vs >100% in China and >90% in developed markets.
B60: Even doubling penetration to 15–20% by 2030 means tens of millions of new units sold.
B89: electromechanical projects and commercial air conditioning, that is Segment 1.
B90: Coming to Segment 2, that is Unitary Products
A93: # | B93: Company Concalls
...

Sheet Control Sheet
B2: Blue Star Ltd
B3: Control Sheet
H4: Current case: | I4: 2
I6: Forecasting
B7: Fiscal Year Ending | C7: =#REF!+1 -> #REF! | D7: =2022 -> 2022 | E7: =D7+1 -> 2023 | F7: =E7+1 -> 2024 | G7: =F7+1 -> 2025 | H7: =G7+1 -> 2026 | I7: =H7+1 -> 2027 | J7: =I7+1 -> 2028 | K7: =J7+1 -> 2029 | L7: =K7+1 -> 2030 | ... R7: =Q7+1 -> 2036
B9: Assumptions
A11: # | B11: Revenue
B13: Revenue - YoY % Growth
B14: Management Case | D14: ='Historical Data'!H9 -> 0.41795529 | E14: ='Historical Data'!I9 -> 0.31952931 | F14: ='Historical Data'!J9 -> 0.21411201 | G14: ='Historical Data'!K9 -> 0.23564328 | H14: ='Historical Data'!L9 -> 0.036292839 | I14: 0.138 | J14: =I14-(($I$14-$R$14)/($R$7-$I$7)) -> 0.136 | K14: =J14-(($I$14-$R$14)/($R$7-$I$7)) -> 0.134 | L14: =K14-(($I$14-$R$14)/($R$7-$I$7)) -> 0.132 | M14: =L14-(($I$14-$R$14)/($R$7-$I$7)) -> 0.13 | N14: =M14-(($I$14-$R$14)/($R$7-$I$7)) -> 0.128 | O14: =N14-(($I$14-$R$14)/($R$7-$I$7)) -> 0.126 | P14: =O14-(($I$14-$R$14)/($R$7-$I$7)) -> 0.124 | Q14: =P14-(($I$14-$R$14)/($R$7-$I$7)) -> 0.122 | R14: 0.12
B15: Base Case | D15: =D14 -> 0.41795529 | E15: =E14 -> 0.31952931 | F15: =F14 -> 0.21411201 | G15: =G14 -> 0.23564328 | H15: =H14 -> 0.036292839 | I15: =13% -> 0.13 | J15: =I15-(($I$15-$R$15)/($R$7-$I$7)) -> 0.12888889 | K15: =J15-(($I$15-$R$15)/($R$7-$I$7)) -> 0.12777778 | L15: =K15-(($I$15-$R$15)/($R$7-$I$7)) -> 0.12666667 | M15: =L15-(($I$15-$R$15)/($R$7-$I$7)) -> 0.12555556 | N15: =M15-(($I$15-$R$15)/($R$7-$I$7)) -> 0.12444444 | O15: =N15-(($I$15-$R$15)/($R$7-$I$7)) -> 0.12333333 | P15: =O15-(($I$15-$R$15)/($R$7-$I$7)) -> 0.12222222 | Q15: =P15-(($I$15-$R$15)/($R$7-$I$7)) -> 0.12111111 | R15: =12% -> 0.12
B16: Down Case | D16: =D14 -> 0.41795529 | E16: =E14 -> 0.31952931 | F16: =F14 -> 0.21411201 | G16: =G14 -> 0.23564328 | H16: =H14 -> 0.036292839 | I16: =10% -> 0.1 | J16: =I16-(($I$16-$R$16)/($R$7-$I$7)) -> 0.097777778 | K16: =J16-(($I$16-$R$16)/($R$7-$I$7)) -> 0.095555556 | L16: =K16-(($I$16-$R$16)/($R$7-$I$7)) -> 0.093333333 | M16: =L16-(($I$16-$R$16)/($R$7-$I$7)) -> 0.091111111 | N16: =M16-(($I$16-$R$16)/($R$7-$I$7)) -> 0.088888889 | O16: =N16-(($I$16-$R$16)/($R$7-$I$7)) -> 0.086666667 | P16: =O16-(($I$16-$R$16)/($R$7-$I$7)) -> 0.084444444 | Q16: =P16-(($I$16-$R$16)/($R$7-$I$7)) -> 0.082222222 | R16: =8% -> 0.08
B17: ="Current Case: "&CHOOSE($I$4,$B$14,$B$15,$B$16) -> Current Case: Base Case | I17: =CHOOSE($I$4,I$14,I$15,I$16) -> 0.13 | J17: =CHOOSE($I$4,J$14,J$15,J$16) -> 0.12888889 | K17: =CHOOSE($I$4,K$14,K$15,K$16) -> 0.12777778 | L17: =CHOOSE($I$4,L$14,L$15,L$16) -> 0.12666667 | M17: =CHOOSE($I$4,M$14,M$15,M$16) -> 0.12555556 | N17: =CHOOSE($I$4,N$14,N$15,N$16) -> 0.12444444 | O17: =CHOOSE($I$4,O$14,O$15,O$16) -> 0.12333333 | P17: =CHOOSE($I$4,P$14,P$15,P$16) -> 0.12222222 | ... R17: =CHOOSE($I$4,R$14,R$15,R$16) -> 0.12
A19: # | B19: COGS
B21: Goss Margin - YoY % Growth
B22: Management Case | D22: ='Historical Data'!H12 -> 0.2201443 | E22: ='Historical Data'!I12 -> 0.22509439 | F22: ='Historical Data'!J12 -> 0.23678934 | G22: ='Historical Data'!K12 -> 0.24176091 | H22: ='Historical Data'!L12 -> 0.23060009 | I22: 0.239 | J22: =I22 -> 0.239 | K22: =J22 -> 0.239 | L22: =K22 -> 0.239 | M22: =L22 -> 0.239 | N22: =M22 -> 0.239 | O22: =N22 -> 0.239 | P22: =O22 -> 0.239 | Q22: =P22 -> 0.239 | R22: =Q22 -> 0.239
B23: Base Case | D23: =D22 -> 0.2201443 | E23: =E22 -> 0.22509439 | F23: =F22 -> 0.23678934 | G23: =G22 -> 0.24176091 | H23: =H22 -> 0.23060009 | I23: =24% -> 0.24 | J23: =24% -> 0.24 | K23: =24% -> 0.24 | L23: =24% -> 0.24 | M23: =24% -> 0.24 | N23: =24% -> 0.24 | O23: =24% -> 0.24 | P23: =24% -> 0.24 | ... R23: =24% -> 0.24
B24: Down Case | D24: =D22 -> 0.2201443 | E24: =E22 -> 0.22509439 | F24: =F22 -> 0.23678934 | G24: =G22 -> 0.24176091 | H24: =H22 -> 0.23060009 | I24: =22% -> 0.22 | J24: =22% -> 0.22 | K24: =22% -> 0.22 | L24: =22% -> 0.22 | M24: =22% -> 0.22 | N24: =22% -> 0.22 | O24: =22% -> 0.22 | P24: =22% -> 0.22 | ... R24: =22% -> 0.22
B25: ="Current Case: "&CHOOSE($I$4,$B$14,$B$15,$B$16) -> Current Case: Base Case | I25: =CHOOSE($I$4,I$22,I$23,I$24) -> 0.24 | J25: =CHOOSE($I$4,J$22,J$23,J$24) -> 0.24 | K25: =CHOOSE($I$4,K$22,K$23,K$24) -> 0.24 | L25: =CHOOSE($I$4,L$22,L$23,L$24) -> 0.24 | M25: =CHOOSE($I$4,M$22,M$23,M$24) -> 0.24 | N25: =CHOOSE($I$4,N$22,N$23,N$24) -> 0.24 | O25: =CHOOSE($I$4,O$22,O$23,O$24) -> 0.24 | P25: =CHOOSE($I$4,P$22,P$23,P$24) -> 0.24 | ... R25: =CHOOSE($I$4,R$22,R$23,R$24) -> 0.24
B27: Current case: C0GS % Revenue | I27: =1-I25 -> 0.76 | J27: =1-J25 -> 0.76 | K27: =1-K25 -> 0.76 | L27: =1-L25 -> 0.76 | M27: =1-M25 -> 0.76 | N27: =1-N25 -> 0.76 | O27: =1-O25 -> 0.76 | P27: =1-P25 -> 0.76 | ... R27: =1-R25 -> 0.76
A29: # | B29: SG&A Expenses
B31: SG&A % Revenue
B32: Management Case | D32: ='Historical Data'!H15 -> 0.16283467 | E32: ='Historical Data'!I15 -> 0.16332177 | F32: ='Historical Data'!J15 -> 0.16813521 | G32: ='Historical Data'!K15 -> 0.16857027 | H32: ='Historical Data'!L15 -> 0.15557987 | I32: 0.16 | J32: =I32 -> 0.16 | K32: =J32 -> 0.16 | L32: =K32 -> 0.16 | M32: =L32 -> 0.16 | N32: =M32 -> 0.16 | O32: =N32 -> 0.16 | P32: =O32 -> 0.16 | Q32: =P32 -> 0.16 | R32: =Q32 -> 0.16
B33: Base Case | D33: =D32 -> 0.16283467 | E33: =E32 -> 0.16332177 | F33: =F32 -> 0.16813521 | G33: =G32 -> 0.16857027 | H33: =H32 -> 0.15557987 | I33: 0.16 | J33: =I33 -> 0.16 | K33: =J33 -> 0.16 | L33: =K33 -> 0.16 | M33: =L33 -> 0.16 | N33: =M33 -> 0.16 | O33: =N33 -> 0.16 | P33: =O33 -> 0.16 | Q33: =P33 -> 0.16 | R33: =Q33 -> 0.16
B34: Down Case | D34: =D32 -> 0.16283467 | E34: =E32 -> 0.16332177 | F34: =F32 -> 0.16813521 | G34: =G32 -> 0.16857027 | H34: =H32 -> 0.15557987 | I34: 0.16 | J34: =I34 -> 0.16 | K34: =J34 -> 0.16 | L34: =K34 -> 0.16 | M34: =L34 -> 0.16 | N34: =M34 -> 0.16 | O34: =N34 -> 0.16 | P34: =O34 -> 0.16 | Q34: =P34 -> 0.16 | R34: =Q34 -> 0.16
B35: ="Current Case: "&CHOOSE($I$4,$B$14,$B$15,$B$16) -> Current Case: Base Case | I35: =CHOOSE($I$4,I32,I$33,I$34) -> 0.16 | J35: =CHOOSE($I$4,J32,J$33,J$34) -> 0.16 | K35: =CHOOSE($I$4,K32,K$33,K$34) -> 0.16 | L35: =CHOOSE($I$4,L32,L$33,L$34) -> 0.16 | M35: =CHOOSE($I$4,M32,M$33,M$34) -> 0.16 | N35: =CHOOSE($I$4,N32,N$33,N$34) -> 0.16 | O35: =CHOOSE($I$4,O32,O$33,O$34) -> 0.16 | P35: =CHOOSE($I$4,P32,P$33,P$34) -> 0.16 | ... R35: =CHOOSE($I$4,R32,R$33,R$34) -> 0.16
A37: # | B37: Non Current Assets
B39: Intangible Assets % Revenue | I39: 0.01 | J39: =I39 -> 0.01 | K39: =J39 -> 0.01 | L39: =K39 -> 0.01 | M39: =L39 -> 0.01 | N39: =M39 -> 0.01 | O39: =N39 -> 0.01 | P39: =O39 -> 0.01 | Q39: =P39 -> 0.01 | R39: =Q39 -> 0.01
B41: Capital WIP
B42: Management Case | D42: - | E42: - | F42: - | G42: - | H42: - | I42: 0 | J42: =I42 -> 0 | K42: =J42 -> 0 | L42: =K42 -> 0 | M42: =L42 -> 0 | N42: =M42 -> 0 | O42: =N42 -> 0 | P42: =O42 -> 0 | Q42: =P42 -> 0 | R42: =Q42 -> 0
B43: Base Case | D43: - | E43: - | F43: - | G43: - | H43: - | I43: 0 | J43: =I43 -> 0 | K43: =J43 -> 0 | L43: =K43 -> 0 | M43: =L43 -> 0 | N43: =M43 -> 0 | O43: =N43 -> 0 | P43: =O43 -> 0 | Q43: =P43 -> 0 | R43: =Q43 -> 0
B44: Down Case | D44: - | E44: - | F44: - | G44: - | H44: - | I44: 0 | J44: =I44 -> 0 | K44: =J44 -> 0 | L44: =K44 -> 0 | M44: =L44 -> 0 | N44: =M44 -> 0 | O44: =N44 -> 0 | P44: =O44 -> 0 | Q44: =P44 -> 0 | R44: =Q44 -> 0
B45: ="Current Case: "&CHOOSE($I$4,$B$14,$B$15,$B$16) -> Current Case: Base Case | I45: =CHOOSE($I$4,I$42,I$43,I$44) -> 0 | J45: =CHOOSE($I$4,J$42,J$43,J$44) -> 0 | K45: =CHOOSE($I$4,K$42,K$43,K$44) -> 0 | L45: =CHOOSE($I$4,L$42,L$43,L$44) -> 0 | M45: =CHOOSE($I$4,M$42,M$43,M$44) -> 0 | N45: =CHOOSE($I$4,N$42,N$43,N$44) -> 0 | O45: =CHOOSE($I$4,O$42,O$43,O$44) -> 0 | P45: =CHOOSE($I$4,P$42,P$43,P$44) -> 0 | ... R45: =CHOOSE($I$4,R$42,R$43,R$44) -> 0
B47: Intangible Assets Under Development Growth %
B48: Management Case | D48: - | E48: - | F48: - | G48: - | H48: - | I48: 0 | J48: =I48 -> 0 | K48: =J48 -> 0 | L48: =K48 -> 0 | M48: =L48 -> 0 | N48: =M48 -> 0 | O48: =N48 -> 0 | P48: =O48 -> 0 | Q48: =P48 -> 0 | R48: =Q48 -> 0
B49: Base Case | D49: - | E49: - | F49: - | G49: - | H49: - | I49: 0 | J49: =I49 -> 0 | K49: =J49 -> 0 | L49: =K49 -> 0 | M49: =L49 -> 0 | N49: =M49 -> 0 | O49: =N49 -> 0 | P49: =O49 -> 0 | Q49: =P49 -> 0 | R49: =Q49 -> 0
B50: Down Case | D50: - | E50: - | F50: - | G50: - | H50: - | I50: 0 | J50: =I50 -> 0 | K50: =J50 -> 0 | L50: =K50 -> 0 | M50: =L50 -> 0 | N50: =M50 -> 0 | O50: =N50 -> 0 | P50: =O50 -> 0 | Q50: =P50 -> 0 | R50: =Q50 -> 0
B51: ="Current Case: "&CHOOSE($I$4,$B$14,$B$15,$B$16) -> Current Case: Base Case | I51: =CHOOSE($I$4,I$48,I$49,I$50) -> 0 | J51: =CHOOSE($I$4,J$48,J$49,J$50) -> 0 | K51: =CHOOSE($I$4,K$48,K$49,K$50) -> 0 | L51: =CHOOSE($I$4,L$48,L$49,L$50) -> 0 | M51: =CHOOSE($I$4,M$48,M$49,M$50) -> 0 | N51: =CHOOSE($I$4,N$48,N$49,N$50) -> 0 | O51: =CHOOSE($I$4,O$48,O$49,O$50) -> 0 | P51: =CHOOSE($I$4,P$48,P$49,P$50) -> 0 | ... R51: =CHOOSE($I$4,R$48,R$49,R$50) -> 0
B53: Non Current Investments
B54: Management Case | D54: - | E54: - | F54: - | G54: - | H54: - | I54: 0 | J54: =I54 -> 0 | K54: =J54 -> 0 | L54: =K54 -> 0 | M54: =L54 -> 0 | N54: =M54 -> 0 | O54: =N54 -> 0 | P54: =O54 -> 0 | Q54: =P54 -> 0 | R54: =Q54 -> 0
B55: Base Case | D55: - | E55: - | F55: - | G55: - | H55: - | I55: 0 | J55: =I55 -> 0 | K55: =J55 -> 0 | L55: =K55 -> 0 | M55: =L55 -> 0 | N55: =M55 -> 0 | O55: =N55 -> 0 | P55: =O55 -> 0 | Q55: =P55 -> 0 | R55: =Q55 -> 0
...

Sheet Schedule
B2: Blue Star Ltd
B3: Schedules
E6: Forecasting
B7: Fiscal Year Ending | C7: =2025 -> 2025 | D7: =C7+1 -> 2026 | E7: =D7+1 -> 2027 | F7: =E7+1 -> 2028 | G7: =F7+1 -> 2029 | H7: =G7+1 -> 2030 | I7: =H7+1 -> 2031 | J7: =I7+1 -> 2032 | K7: =J7+1 -> 2033 | ... N7: =M7+1 -> 2036
B9: Assumptions
A11: # | B11: Revenue Schedule
B13: Revenue | C13: ='Historical Data'!K8 -> 11967.65 | D13: ='Historical Data'!L8 -> 12401.99 | E13: =D13*(1+E15) -> 14014.249 | F13: =E13*(1+F15) -> 15820.53 | G13: =F13*(1+G15) -> 17842.042 | H13: =G13*(1+H15) -> 20102.034 | I13: =H13*(1+I15) -> 22625.956 | J13: =I13*(1+J15) -> 25441.63 | K13: =J13*(1+K15) -> 28579.431 | L13: =K13*(1+L15) -> 32072.473 | ... N13: =M13*(1+N15) -> 40271.622
B15: Growth YoY % | C15: ='Control Sheet'!G14 -> 0.23564328 | D15: ='Control Sheet'!H14 -> 0.036292839 | E15: ='Control Sheet'!I17 -> 0.13 | F15: ='Control Sheet'!J17 -> 0.12888889 | G15: ='Control Sheet'!K17 -> 0.12777778 | H15: ='Control Sheet'!L17 -> 0.12666667 | I15: ='Control Sheet'!M17 -> 0.12555556 | J15: ='Control Sheet'!N17 -> 0.12444444 | K15: ='Control Sheet'!O17 -> 0.12333333 | L15: ='Control Sheet'!P17 -> 0.12222222 | ... N15: ='Control Sheet'!R17 -> 0.12
A19: # | B19: COGS Schedule
B21: COGS | C21: ='Historical Data'!K10 -> 9074.34 | D21: ='Historical Data'!L10 -> 9542.09 | E21: =E13*E23 -> 10650.829 | F21: =F13*F23 -> 12023.603 | G21: =G13*G23 -> 13559.952 | H21: =H13*H23 -> 15277.546 | I21: =I13*I23 -> 17195.726 | J21: =J13*J23 -> 19335.639 | K21: =K13*K23 -> 21720.368 | L21: =L13*L23 -> 24375.079 | ... N21: =N13*N23 -> 30606.433
B23: COGS % Revenue | C23: =C21/C13 -> 0.75823909 | D23: =D21/D13 -> 0.76939991 | E23: ='Control Sheet'!I27 -> 0.76 | F23: ='Control Sheet'!J27 -> 0.76 | G23: ='Control Sheet'!K27 -> 0.76 | H23: ='Control Sheet'!L27 -> 0.76 | I23: ='Control Sheet'!M27 -> 0.76 | J23: ='Control Sheet'!N27 -> 0.76 | K23: ='Control Sheet'!O27 -> 0.76 | L23: ='Control Sheet'!P27 -> 0.76 | ... N23: ='Control Sheet'!R27 -> 0.76
A27: # | B27: SG&A Expenses
B29: Total SG&A Expenses | C29: ='Historical Data'!K14 -> 2017.39 | D29: ='Historical Data'!L14 -> 1929.5 | E29: =E$13*E31 -> 2242.2798 | F29: =F$13*F31 -> 2531.2847 | G29: =G$13*G31 -> 2854.7267 | H29: =H$13*H31 -> 3216.3254 | I29: =I$13*I31 -> 3620.1529 | J29: =J$13*J31 -> 4070.6608 | K29: =K$13*K31 -> 4572.709 | L29: =L$13*L31 -> 5131.5957 | ... N29: =N$13*N31 -> 6443.4596
B31: SG&A % Revenue | C31: =C29/C13 -> 0.16857027 | D31: =D29/D13 -> 0.15557987 | E31: ='Control Sheet'!I35 -> 0.16 | F31: ='Control Sheet'!J35 -> 0.16 | G31: ='Control Sheet'!K35 -> 0.16 | H31: ='Control Sheet'!L35 -> 0.16 | I31: ='Control Sheet'!M35 -> 0.16 | J31: ='Control Sheet'!N35 -> 0.16 | K31: ='Control Sheet'!O35 -> 0.16 | L31: ='Control Sheet'!P35 -> 0.16 | ... N31: ='Control Sheet'!R35 -> 0.16
A33: # | B33: Non Current Assets
B35: Tangible Assets & Capex
B37: Net Tangible Assets | C37: ='Historical Data'!K65 -> 1422.38 | D37: ='Historical Data'!L65 -> 1439.17 | E37: =E43 -> 1579.3125 | F37: =F43 -> 1737.5178 | G37: =G43 -> 1915.9382 | H37: =H43 -> 2157.1626 | I37: =I43 -> 2428.6741 | J37: =J43 -> 2733.9736 | K37: =K43 -> 2991.1885 | L37: =L43 -> 3279.8408 | ... N37: =N43 -> 3656.6681
B38: Net Growth YoY % | E38: =E37/D37-1 -> 0.097377299 | F38: =F37/E37-1 -> 0.10017352 | G38: =G37/F37-1 -> 0.10268696 | H38: =H37/G37-1 -> 0.12590406 | I38: =I37/H37-1 -> 0.12586509 | J38: =J37/I37-1 -> 0.12570627 | K38: =K37/J37-1 -> 0.094080966 | L38: =L37/K37-1 -> 0.096500857 | ... N38: =N37/M37-1 -> 0.046082886
B40: Opening Tangible Assets | E40: =D37 -> 1439.17 | F40: =E37 -> 1579.3125 | G40: =F37 -> 1737.5178 | H40: =G37 -> 1915.9382 | I40: =H37 -> 2157.1626 | J40: =I37 -> 2428.6741 | K40: =J37 -> 2733.9736 | L40: =K37 -> 2991.1885 | ... N40: =M37 -> 3495.5816
B41: Add: Capex | E41: =E$13*'Control Sheet'!I137 -> 294.29922 | F41: =F$13*'Control Sheet'!J137 -> 332.23112 | G41: =G$13*'Control Sheet'!K137 -> 374.68288 | H41: =H$13*'Control Sheet'!L137 -> 462.34678 | I41: =I$13*'Control Sheet'!M137 -> 520.39698 | J41: =J$13*'Control Sheet'!N137 -> 585.1575 | K41: =K$13*'Control Sheet'!O137 -> 571.58863 | L41: =L$13*'Control Sheet'!P137 -> 641.44946 | ... N41: =N$13*'Control Sheet'!R137 -> 604.07434
B42: Less: Depreciation | E42: =E13*1.1% -> 154.15674 | F42: =F13*1.1% -> 174.02583 | G42: =G13*1.1% -> 196.26246 | H42: =H13*1.1% -> 221.12237 | I42: =I13*1.1% -> 248.88551 | J42: =J13*1.1% -> 279.85793 | K42: =K13*1.1% -> 314.37374 | L42: =L13*1.1% -> 352.7972 | ... N42: =N13*1.1% -> 442.98785
B43: Closing Tangible Assets | E43: =E40+E41-E42 -> 1579.3125 | F43: =F40+F41-F42 -> 1737.5178 | G43: =G40+G41-G42 -> 1915.9382 | H43: =H40+H41-H42 -> 2157.1626 | I43: =I40+I41-I42 -> 2428.6741 | J43: =J40+J41-J42 -> 2733.9736 | K43: =K40+K41-K42 -> 2991.1885 | L43: =L40+L41-L42 -> 3279.8408 | ... N43: =N40+N41-N42 -> 3656.6681
B46: Depreciation % Closing Tangibles | E46: =E42/E43 -> 0.097610028 | F46: =F42/F43 -> 0.10015772 | G46: =G42/G43 -> 0.10243674 | H46: =H42/H43 -> 0.10250612 | I46: =I42/I43 -> 0.10247794 | J46: =J42/J43 -> 0.10236307 | K46: =K42/K43 -> 0.10509994 | L46: =L42/L43 -> 0.10756534 | ... N46: =N42/N43 -> 0.12114522
B48: Intangible Assets & Capex
B50: Net Intangible Assets | C50: ='Historical Data'!K66 -> 113.33 | D50: ='Historical Data'!L66 -> 155.56 | E50: =E13*E51 -> 140.14249 | F50: =F13*F51 -> 158.2053 | G50: =G13*G51 -> 178.42042 | H50: =H13*H51 -> 201.02034 | I50: =I13*I51 -> 226.25956 | J50: =J13*J51 -> 254.4163 | K50: =K13*K51 -> 285.79431 | L50: =L13*L51 -> 320.72473 | ... N50: =N13*N51 -> 402.71622
B51: Intangible Assets % Revenue | E51: ='Control Sheet'!I39 -> 0.01 | F51: 0.01 | G51: 0.01 | H51: 0.01 | I51: 0.01 | J51: 0.01 | K51: 0.01 | L51: 0.01 | M51: 0.01 | N51: 0.01
B53: Opening Intangible Assets | E53: =D56 -> 155.56 | F53: =E56 -> 140.14249 | G53: =F56 -> 158.2053 | H53: =G56 -> 178.42042 | I53: =H56 -> 201.02034 | J53: =I56 -> 226.25956 | K53: =J56 -> 254.4163 | L53: =K56 -> 285.79431 | ... N53: =M56 -> 359.56806
B54: Addition during the year | E54: =E56-E53+E55 -> 26.625233 | F54: =F56-F53+F55 -> 65.524398 | G54: =G56-G53+G55 -> 73.741247 | H54: =H56-H53+H55 -> 82.906021 | I54: =I56-I53+I55 -> 93.117087 | J54: =J56-J53+J55 -> 104.48164 | K54: =K56-K53+K55 -> 117.1163 | L54: =L56-L53+L55 -> 131.14783 | ... N54: =N56-N53+N55 -> 163.96303
B55: Less: Depreciation | E55: =E13*0.3% -> 42.042746 | F55: =F13*0.3% -> 47.461589 | G55: =G13*0.3% -> 53.526125 | H55: =H13*0.3% -> 60.306101 | I55: =I13*0.3% -> 67.877867 | J55: =J13*0.3% -> 76.324891 | K55: =K13*0.3% -> 85.738294 | L55: =L13*0.3% -> 96.217419 | ... N55: =N13*0.3% -> 120.81487
B56: Closing Intangible Assets | D56: =D50 -> 155.56 | E56: =E50 -> 140.14249 | F56: =F50 -> 158.2053 | G56: =G50 -> 178.42042 | H56: =H50 -> 201.02034 | I56: =I50 -> 226.25956 | J56: =J50 -> 254.4163 | K56: =K50 -> 285.79431 | ... N56: =N50 -> 402.71622
B58: Capital WIP
B59: Capital WIP | C59: ='Historical Data'!K67 -> 73.36 | D59: ='Historical Data'!L67 -> 65.47 | E59: =D59*(1+E60) -> 65.47 | F59: =E59 -> 65.47 | G59: =F59 -> 65.47 | H59: =G59 -> 65.47 | I59: =H59 -> 65.47 | J59: =I59 -> 65.47 | K59: =J59 -> 65.47 | L59: =K59 -> 65.47 | M59: =L59 -> 65.47 | N59: =M59 -> 65.47
B60: Growth YoY % | E60: ='Control Sheet'!I45 -> 0 | F60: ='Control Sheet'!J45 -> 0 | G60: ='Control Sheet'!K45 -> 0 | H60: ='Control Sheet'!L45 -> 0 | I60: ='Control Sheet'!M45 -> 0 | J60: ='Control Sheet'!N45 -> 0 | K60: ='Control Sheet'!O45 -> 0 | L60: ='Control Sheet'!P45 -> 0 | ... N60: ='Control Sheet'!R45 -> 0
B62: Intangible Capital WIP
B63: Capital WIP | C63: ='Historical Data'!K68 -> 49.81 | D63: ='Historical Data'!L68 -> 0 | E63: =D63*(1+E64) -> 0 | F63: =E63 -> 0 | G63: =F63 -> 0 | H63: =G63 -> 0 | I63: =H63 -> 0 | J63: =I63 -> 0 | K63: =J63 -> 0 | L63: =K63 -> 0 | M63: =L63 -> 0 | N63: =M63 -> 0
B64: Growth YoY % | E64: ='Control Sheet'!I51 -> 0 | F64: ='Control Sheet'!J51 -> 0 | G64: ='Control Sheet'!K51 -> 0 | H64: ='Control Sheet'!L51 -> 0 | I64: ='Control Sheet'!M51 -> 0 | J64: ='Control Sheet'!N51 -> 0 | K64: ='Control Sheet'!O51 -> 0 | L64: ='Control Sheet'!P51 -> 0 | ... N64: ='Control Sheet'!R51 -> 0
B66: Non Current Investments
B67: Non Current Investments | C67: ='Historical Data'!K69 -> 17.94 | D67: ='Historical Data'!L69 -> 21.94 | E67: =D67*(1+E68) -> 21.94 | F67: =E67 -> 21.94 | G67: =F67 -> 21.94 | H67: =G67 -> 21.94 | I67: =H67 -> 21.94 | J67: =I67 -> 21.94 | K67: =J67 -> 21.94 | L67: =K67 -> 21.94 | M67: =L67 -> 21.94 | N67: =M67 -> 21.94
B68: Growth YoY % | E68: ='Control Sheet'!I57 -> 0 | F68: ='Control Sheet'!J57 -> 0 | G68: ='Control Sheet'!K57 -> 0 | H68: ='Control Sheet'!L57 -> 0 | I68: ='Control Sheet'!M57 -> 0 | J68: ='Control Sheet'!N57 -> 0 | K68: ='Control Sheet'!O57 -> 0 | L68: ='Control Sheet'!P57 -> 0 | ... N68: ='Control Sheet'!R57 -> 0
B70: Deferred Tax Asset (Net)
...

Sheet Ratio Analysis
B2: Ratio Analysis - Bluestar Ltd
B3: All figures in INR Crores.
B5: Fiscal Year Ending | C5: =2022 -> 2022 | D5: =C5+1 -> 2023 | E5: =D5+1 -> 2024 | F5: =E5+1 -> 2025 | G5: =F5+1 -> 2026 | H5: =G5+1 -> 2027 | I5: =H5+1 -> 2028 | J5: =I5+1 -> 2029 | K5: =J5+1 -> 2030 | ... Q5: =P5+1 -> 2036
A7: # | B7: Liquidity Ratio
B9: Current Assets | C9: ='3 - Statement Model'!H80 -> 3483.43 | D9: ='3 - Statement Model'!I80 -> 4250.61 | E9: ='3 - Statement Model'!J80 -> 5040.03 | F9: ='3 - Statement Model'!K80 -> 6312.77 | G9: ='3 - Statement Model'!L80 -> 6388.27 | H9: ='3 - Statement Model'!M80 -> 7892.5474 | I9: ='3 - Statement Model'!N80 -> 8871.5247 | J9: ='3 - Statement Model'!O80 -> 9970.4872 | ... Q9: ='3 - Statement Model'!V80 -> 22646.883
B10: Current Liablities | C10: ='3 - Statement Model'!H57 -> 2969.2 | D10: ='3 - Statement Model'!I57 -> 3783.75 | E10: ='3 - Statement Model'!J57 -> 3879.62 | F10: ='3 - Statement Model'!K57 -> 4944.39 | G10: ='3 - Statement Model'!L57 -> 4866.26 | H10: ='3 - Statement Model'!M57 -> 6012.4907 | I10: ='3 - Statement Model'!N57 -> 6620.3166 | J10: ='3 - Statement Model'!O57 -> 7300.5693 | ... Q10: ='3 - Statement Model'!V57 -> 14848.277
B11: Current Ratio | C11: =C9/C10 -> 1.1731881 | D11: =D9/D10 -> 1.1233855 | E11: =E9/E10 -> 1.299104 | F11: =F9/F10 -> 1.2767541 | G11: =G9/G10 -> 1.3127679 | H11: =H9/H10 -> 1.3126918 | I11: =I9/I10 -> 1.3400454 | J11: =J9/J10 -> 1.3657137 | ... Q11: =Q9/Q10 -> 1.5252196
B13: Current Assets | C13: ='Ratio Analysis'!C9 -> 3483.43 | D13: ='Ratio Analysis'!D9 -> 4250.61 | E13: ='Ratio Analysis'!E9 -> 5040.03 | F13: ='Ratio Analysis'!F9 -> 6312.77 | G13: ='Ratio Analysis'!G9 -> 6388.27 | H13: ='Ratio Analysis'!H9 -> 7892.5474 | I13: ='Ratio Analysis'!I9 -> 8871.5247 | J13: ='Ratio Analysis'!J9 -> 9970.4872 | ... Q13: ='Ratio Analysis'!Q9 -> 22646.883
B14: Inventory | C14: ='3 - Statement Model'!H75 -> 1144.24 | D14: ='3 - Statement Model'!I75 -> 1433.39 | E14: ='3 - Statement Model'!J75 -> 1407.18 | F14: ='3 - Statement Model'!K75 -> 2149.15 | G14: ='3 - Statement Model'!L75 -> 2166.2 | H14: ='3 - Statement Model'!M75 -> 2188.5265 | I14: ='3 - Statement Model'!N75 -> 2470.6033 | J14: ='3 - Statement Model'!O75 -> 2786.2915 | ... Q14: ='3 - Statement Model'!V75 -> 5869.7269
B15: Prepaid Expenses | C15: 0 | D15: =C15 -> 0 | E15: =D15 -> 0 | F15: =E15 -> 0 | G15: =F15 -> 0 | H15: =G15 -> 0 | I15: =H15 -> 0 | J15: =I15 -> 0 | K15: =J15 -> 0 | ... Q15: =P15 -> 0
B16: Current liablities | C16: =C10 -> 2969.2 | D16: =D10 -> 3783.75 | E16: =E10 -> 3879.62 | F16: =F10 -> 4944.39 | G16: =G10 -> 4866.26 | H16: =H10 -> 6012.4907 | I16: =I10 -> 6620.3166 | J16: =J10 -> 7300.5693 | ... Q16: =Q10 -> 14848.277
B17: Quick Ratio | C17: =(C13-C14-C15)/C16 -> 0.78781827 | D17: =(D13-D14-D15)/D16 -> 0.74455765 | E17: =(E13-E14-E15)/E16 -> 0.93639326 | F17: =(F13-F14-F15)/F16 -> 0.84208972 | G17: =(G13-G14-G15)/G16 -> 0.86762113 | H17: =(H13-H14-H15)/H16 -> 0.94869518 | I17: =(I13-I14-I15)/I16 -> 0.96686032 | J17: =(J13-J14-J15)/J16 -> 0.98405967 | ... Q17: =(Q13-Q14-Q15)/Q16 -> 1.129906
B19: Inventory Days | C19: ='Assumptions Working'!I470 -> 78.449746 | D19: ='Assumptions Working'!J470 -> 76.098769 | E19: ='Assumptions Working'!K470 -> 70.130699 | F19: ='Assumptions Working'!L470 -> 71.523684 | G19: ='Assumptions Working'!M470 -> 82.534474 | H19: =Schedule!E150 -> 75 | I19: =Schedule!F150 -> 75 | J19: =Schedule!G150 -> 75 | K19: =Schedule!H150 -> 72 | L19: =Schedule!I150 -> 72 | M19: =Schedule!J150 -> 72 | N19: =Schedule!K150 -> 72 | O19: =Schedule!L150 -> 70 | ... Q19: =Schedule!N150 -> 70
B20: Trade Receivable Days | C20: ='Assumptions Working'!I572 -> 60.396422 | D20: ='Assumptions Working'!J572 -> 62.651016 | E20: ='Assumptions Working'!K572 -> 65.976056 | F20: =Schedule!C144 -> 59.758603 | G20: =Schedule!D144 -> 62.972999 | H20: =Schedule!E144 -> 65 | I20: =Schedule!F144 -> 65 | J20: =Schedule!G144 -> 65 | K20: =Schedule!H144 -> 65 | L20: =Schedule!I144 -> 65 | M20: =Schedule!J144 -> 65 | ... Q20: =Schedule!N144 -> 65
B21: Trade Payable Days | C21: ='Assumptions Working'!I883 -> 141.15427 | D21: ='Assumptions Working'!J883 -> 134.41214 | E21: ='Assumptions Working'!K883 -> 126.59903 | F21: =Schedule!C168 -> 137.87023 | G21: =Schedule!D168 -> 112.56904 | H21: =Schedule!E168 -> 140 | I21: =Schedule!F168 -> 140 | J21: =Schedule!G168 -> 140 | K21: =Schedule!H168 -> 140 | L21: =Schedule!I168 -> 140 | M21: =Schedule!J168 -> 140 | ... Q21: =Schedule!N168 -> 140
B22: Working Capital Days | C22: =365/('3 - Statement Model'!H8/('Ratio Analysis'!C9-'Ratio Analysis'!C10)) -> 31.046475 | D22: =365/('3 - Statement Model'!I8/('Ratio Analysis'!D9-'Ratio Analysis'!D10)) -> 21.361046 | E22: =365/('3 - Statement Model'!J8/('Ratio Analysis'!E9-'Ratio Analysis'!E10)) -> 43.730914 | F22: =365/('3 - Statement Model'!K8/('Ratio Analysis'!F9-'Ratio Analysis'!F10)) -> 41.734066 | G22: =365/('3 - Statement Model'!L8/('Ratio Analysis'!G9-'Ratio Analysis'!G10)) -> 44.793912 | H22: =365/('3 - Statement Model'!M8/('Ratio Analysis'!H9-'Ratio Analysis'!H10)) -> 48.965929 | I22: =365/('3 - Statement Model'!N8/('Ratio Analysis'!I9-'Ratio Analysis'!I10)) -> 51.938271 | J22: =365/('3 - Statement Model'!O8/('Ratio Analysis'!J9-'Ratio Analysis'!J10)) -> 54.619313 | ... Q22: =365/('3 - Statement Model'!V8/('Ratio Analysis'!Q9-'Ratio Analysis'!Q10)) -> 70.682312
B23: Cash Conversion Cycle | C23: =(C19+C20-C21) -> -2.3080989 | D23: =(D19+D20-D21) -> 4.3376472 | E23: =(E19+E20-E21) -> 9.5077292 | F23: =(F19+F20-F21) -> -6.5879381 | G23: =(G19+G20-G21) -> 32.938433 | H23: =(H19+H20-H21) -> 0 | I23: =(I19+I20-I21) -> 0 | J23: =(J19+J20-J21) -> 0 | ... Q23: =(Q19+Q20-Q21) -> -5
A25: # | B25: Leverage Ratio
B27: Total Debt | C27: ='3 - Statement Model'!H46+'3 - Statement Model'!H53 -> 477.83 | D27: ='3 - Statement Model'!I46+'3 - Statement Model'!I53 -> 577.64 | E27: ='3 - Statement Model'!J46+'3 - Statement Model'!J53 -> 166.62 | F27: ='3 - Statement Model'!K46+'3 - Statement Model'!K53 -> 199.36 | G27: ='3 - Statement Model'!L46+'3 - Statement Model'!L53 -> 626.8 | H27: ='3 - Statement Model'!M46+'3 - Statement Model'!M53 -> 630.64119 | I27: ='3 - Statement Model'!N46+'3 - Statement Model'!N53 -> 711.92383 | J27: ='3 - Statement Model'!O46+'3 - Statement Model'!O53 -> 802.89188 | ... Q27: ='3 - Statement Model'!V46+'3 - Statement Model'!V53 -> 1812.223
B28: Total Equity | C28: ='3 - Statement Model'!H42 -> 1017.58 | D28: ='3 - Statement Model'!I42 -> 1330.65 | E28: ='3 - Statement Model'!J42 -> 2610.07 | F28: ='3 - Statement Model'!K42 -> 3065.02 | G28: ='3 - Statement Model'!L42 -> 3431.41 | H28: ='3 - Statement Model'!M42 -> 3914.1817 | I28: ='3 - Statement Model'!N42 -> 4461.6012 | J28: ='3 - Statement Model'!O42 -> 5078.9466 | ... Q28: ='3 - Statement Model'!V42 -> 12172.661
B29: Debt to Equity | C29: =C27/C28 -> 0.46957487 | D29: =D27/D28 -> 0.43410363 | E29: =E27/E28 -> 0.063837368 | F29: =F27/F28 -> 0.065043621 | G29: =G27/G28 -> 0.18266543 | H29: =H27/H28 -> 0.16111699 | I29: =I27/I28 -> 0.15956689 | J29: =J27/J28 -> 0.15808236 | ... Q29: =Q27/Q28 -> 0.14887649
B31: Total Debt | C31: =C27 -> 477.83 | D31: =D27 -> 577.64 | E31: =E27 -> 166.62 | F31: =F27 -> 199.36 | G31: =G27 -> 626.8 | H31: =H27 -> 630.64119 | I31: =I27 -> 711.92383 | J31: =J27 -> 802.89188 | ... Q31: =Q27 -> 1812.223
B32: Total Assets | C32: ='3 - Statement Model'!H82 -> 4312.64 | D32: ='3 - Statement Model'!I82 -> 5399.06 | E32: ='3 - Statement Model'!J82 -> 6618.25 | F32: ='3 - Statement Model'!K82 -> 8257.5 | G32: ='3 - Statement Model'!L82 -> 8575.98 | H32: ='3 - Statement Model'!M82 -> 10204.982 | I32: ='3 - Statement Model'!N82 -> 11360.228 | J32: ='3 - Statement Model'!O82 -> 12657.826 | ... Q32: ='3 - Statement Model'!V82 -> 27299.248
B33: Debt to Assets | C33: =C31/C32 -> 0.11079756 | D33: =D31/D32 -> 0.10698899 | E33: =E31/E32 -> 0.02517584 | F33: =F31/F32 -> 0.0241429 | G33: =G31/G32 -> 0.073087857 | H33: =H31/H32 -> 0.061797382 | I33: =I31/I32 -> 0.062668095 | J33: =J31/J32 -> 0.063430473 | ... Q33: =Q31/Q32 -> 0.066383625
B35: Total Equity | C35: =C28 -> 1017.58 | D35: =D28 -> 1330.65 | E35: =E28 -> 2610.07 | F35: =F28 -> 3065.02 | G35: =G28 -> 3431.41 | H35: =H28 -> 3914.1817 | I35: =I28 -> 4461.6012 | J35: =J28 -> 5078.9466 | ... Q35: =Q28 -> 12172.661
B36: Total Assets | C36: =C32 -> 4312.64 | D36: =D32 -> 5399.06 | E36: =E32 -> 6618.25 | F36: =F32 -> 8257.5 | G36: =G32 -> 8575.98 | H36: =H32 -> 10204.982 | I36: =I32 -> 11360.228 | J36: =J32 -> 12657.826 | ... Q36: =Q32 -> 27299.248
B37: Equity Ratio | C37: =C35/C36 -> 0.23595292 | D37: =D35/D36 -> 0.24645957 | E37: =E35/E36 -> 0.39437465 | F37: =F35/F36 -> 0.37118014 | G37: =G35/G36 -> 0.4001187 | H37: =H35/H36 -> 0.38355595 | I37: =I35/I36 -> 0.39273871 | J37: =J35/J36 -> 0.40124952 | ... Q37: =Q35/Q36 -> 0.4458973
A39: # | B39: Profitability/ Margin Ratio
B41: Gross Profit | C41: ='3 - Statement Model'!H11 -> 1330.9 | D41: ='3 - Statement Model'!I11 -> 1795.65 | E41: ='3 - Statement Model'!J11 -> 2293.39 | F41: ='3 - Statement Model'!K11 -> 2893.31 | G41: ='3 - Statement Model'!L11 -> 2859.9 | H41: ='3 - Statement Model'!M11 -> 3363.4197 | I41: ='3 - Statement Model'!N11 -> 3796.9271 | J41: ='3 - Statement Model'!O11 -> 4282.09 | ... Q41: ='3 - Statement Model'!V11 -> 9665.1894
B42: Total Sales | C42: ='3 - Statement Model'!H8 -> 6045.58 | D42: ='3 - Statement Model'!I8 -> 7977.32 | E42: ='3 - Statement Model'!J8 -> 9685.36 | F42: ='3 - Statement Model'!K8 -> 11967.65 | G42: ='3 - Statement Model'!L8 -> 12401.99 | H42: ='3 - Statement Model'!M8 -> 14014.249 | I42: ='3 - Statement Model'!N8 -> 15820.53 | J42: ='3 - Statement Model'!O8 -> 17842.042 | ... Q42: ='3 - Statement Model'!V8 -> 40271.622
B43: Gross Margin | C43: =C41/C42 -> 0.2201443 | D43: =D41/D42 -> 0.22509439 | E43: =E41/E42 -> 0.23678934 | F43: =F41/F42 -> 0.24176091 | G43: =G41/G42 -> 0.23060009 | H43: =H41/H42 -> 0.24 | I43: =I41/I42 -> 0.24 | J43: =J41/J42 -> 0.24 | ... Q43: =Q41/Q42 -> 0.24
B45: EBITDA | C45: ='3 - Statement Model'!H16 -> 346.47 | D45: ='3 - Statement Model'!I16 -> 492.78 | E45: ='3 - Statement Model'!J16 -> 664.94 | F45: ='3 - Statement Model'!K16 -> 875.92 | G45: ='3 - Statement Model'!L16 -> 930.4 | H45: ='3 - Statement Model'!M16 -> 1121.1399 | I45: ='3 - Statement Model'!N16 -> 1265.6424 | J45: ='3 - Statement Model'!O16 -> 1427.3633 | ... Q45: ='3 - Statement Model'!V16 -> 3221.7298
B46: Total Sales | C46: =C42 -> 6045.58 | D46: =D42 -> 7977.32 | E46: =E42 -> 9685.36 | F46: =F42 -> 11967.65 | G46: =G42 -> 12401.99 | H46: =H42 -> 14014.249 | I46: =I42 -> 15820.53 | J46: =J42 -> 17842.042 | ... Q46: =Q42 -> 40271.622
B47: EBITDA Margin | C47: =C45/C46 -> 0.057309638 | D47: =D45/D46 -> 0.061772625 | E47: =E45/E46 -> 0.068654134 | F47: =F45/F46 -> 0.073190643 | G47: =G45/G46 -> 0.075020219 | H47: =H45/H46 -> 0.08 | I47: =I45/I46 -> 0.08 | J47: =J45/J46 -> 0.08 | ... Q47: =Q45/Q46 -> 0.08
B49: EBIT | C49: ='3 - Statement Model'!H20 -> 260.49 | D49: ='3 - Statement Model'!I20 -> 408 | E49: ='3 - Statement Model'!J20 -> 567.33 | F49: ='3 - Statement Model'!K20 -> 747.55 | G49: ='3 - Statement Model'!L20 -> 751.61 | H49: ='3 - Statement Model'!M20 -> 924.94041 | I49: ='3 - Statement Model'!N20 -> 1044.155 | J49: ='3 - Statement Model'!O20 -> 1177.5748 | ... Q49: ='3 - Statement Model'!V20 -> 2657.9271
B50: Total Sales | C50: =C46 -> 6045.58 | D50: =D46 -> 7977.32 | E50: =E46 -> 9685.36 | F50: =F46 -> 11967.65 | G50: =G46 -> 12401.99 | H50: =H46 -> 14014.249 | I50: =I46 -> 15820.53 | J50: =J46 -> 17842.042 | ... Q50: =Q46 -> 40271.622
B51: EBIT Margin | C51: =C49/C50 -> 0.043087677 | D51: =D49/D50 -> 0.051144996 | E51: =E49/E50 -> 0.058576036 | F51: =F49/F50 -> 0.062464226 | G51: =G49/G50 -> 0.060603984 | H51: =H49/H50 -> 0.066 | I51: =I49/I50 -> 0.066 | J51: =J49/J50 -> 0.066 | ... Q51: =Q49/Q50 -> 0.066
B53: Net Profit | C53: ='3 - Statement Model'!H30 -> 166.91 | D53: ='3 - Statement Model'!I30 -> 400.29 | E53: ='3 - Statement Model'!J30 -> 413.82 | F53: ='3 - Statement Model'!K30 -> 592.61 | G53: ='3 - Statement Model'!L30 -> 526.77 | H53: ='3 - Statement Model'!M30 -> 689.67389 | I53: ='3 - Statement Model'!N30 -> 782.02778 | J53: ='3 - Statement Model'!O30 -> 881.92202 | ... Q53: ='3 - Statement Model'!V30 -> 1990.1013
B54: Total Sales | C54: =C50 -> 6045.58 | D54: =D50 -> 7977.32 | E54: =E50 -> 9685.36 | F54: =F50 -> 11967.65 | G54: =G50 -> 12401.99 | H54: =H50 -> 14014.249 | I54: =I50 -> 15820.53 | J54: =J50 -> 17842.042 | ... Q54: =Q50 -> 40271.622
B55: Net Profit Margin | C55: =C53/C54 -> 0.0276086 | D55: =D53/D54 -> 0.050178506 | E55: =E53/E54 -> 0.042726342 | F55: =F53/F54 -> 0.049517658 | G55: =G53/G54 -> 0.042474635 | H55: =H53/H54 -> 0.049212334 | I55: =I53/I54 -> 0.049431201 | J55: =J53/J54 -> 0.049429433 | ... Q55: =Q53/Q54 -> 0.049416964
...

Sheet 3 - Statement Model
B2: Three Statement Model - Bluestar Ltd
B3: All figures in INR Crores.
B5: Fiscal Year Ending | C5: 2017 | D5: =C5+1 -> 2018 | E5: =D5+1 -> 2019 | F5: =E5+1 -> 2020 | G5: =F5+1 -> 2021 | H5: =G5+1 -> 2022 | I5: =H5+1 -> 2023 | J5: =I5+1 -> 2024 | K5: =J5+1 -> 2025 | ... V5: =U5+1 -> 2036
B7: INCOME STATEMENT
B8: Revenue From Operations | C8: ='Historical Data'!C8 -> 4385.24 | D8: ='Historical Data'!D8 -> 4638.95 | E8: ='Historical Data'!E8 -> 5234.84 | F8: ='Historical Data'!F8 -> 5360.19 | G8: ='Historical Data'!G8 -> 4263.59 | H8: ='Historical Data'!H8 -> 6045.58 | I8: ='Historical Data'!I8 -> 7977.32 | J8: ='Historical Data'!J8 -> 9685.36 | ... L8: ='Historical Data'!L8 -> 12401.99 | M8: =Schedule!E13 -> 14014.249 | N8: =Schedule!F13 -> 15820.53 | O8: =Schedule!G13 -> 17842.042 | P8: =Schedule!H13 -> 20102.034 | Q8: =Schedule!I13 -> 22625.956 | R8: =Schedule!J13 -> 25441.63 | S8: =Schedule!K13 -> 28579.431 | T8: =Schedule!L13 -> 32072.473 | ... V8: =Schedule!N13 -> 40271.622
B9: Revenue Growth % | D9: =D8/C8-1 -> 0.057855442 | E9: =E8/D8-1 -> 0.12845364 | F9: =F8/E8-1 -> 0.023945335 | G9: =G8/F8-1 -> -0.2045823 | H9: =H8/G8-1 -> 0.41795529 | I9: =I8/H8-1 -> 0.31952931 | J9: =J8/I8-1 -> 0.21411201 | K9: =K8/J8-1 -> 0.23564328 | ... V9: =V8/U8-1 -> 0.12
B10: Less: Cost of Goods Sold/ Services | C10: ='Historical Data'!C10 -> 3112.25 | D10: ='Historical Data'!D10 -> 3454.95 | E10: ='Historical Data'!E10 -> 3931.18 | F10: ='Historical Data'!F10 -> 4018.11 | G10: ='Historical Data'!G10 -> 3271.35 | H10: ='Historical Data'!H10 -> 4714.68 | I10: ='Historical Data'!I10 -> 6181.67 | J10: ='Historical Data'!J10 -> 7391.97 | ... L10: ='Historical Data'!L10 -> 9542.09 | M10: =Schedule!E21 -> 10650.829 | N10: =Schedule!F21 -> 12023.603 | O10: =Schedule!G21 -> 13559.952 | P10: =Schedule!H21 -> 15277.546 | Q10: =Schedule!I21 -> 17195.726 | R10: =Schedule!J21 -> 19335.639 | S10: =Schedule!K21 -> 21720.368 | T10: =Schedule!L21 -> 24375.079 | ... V10: =Schedule!N21 -> 30606.433
B11: Gross Profit | C11: =C8-C10 -> 1272.99 | D11: =D8-D10 -> 1184 | E11: =E8-E10 -> 1303.66 | F11: =F8-F10 -> 1342.08 | G11: =G8-G10 -> 992.24 | H11: =H8-H10 -> 1330.9 | I11: =I8-I10 -> 1795.65 | J11: =J8-J10 -> 2293.39 | ... V11: =V8-V10 -> 9665.1894
B12: Gross Margin (%) | C12: =C11/C8 -> 0.2902897 | D12: =D11/D8 -> 0.25523017 | E12: =E11/E8 -> 0.24903531 | F12: =F11/F8 -> 0.25037918 | G12: =G11/G8 -> 0.23272407 | H12: =H11/H8 -> 0.2201443 | I12: =I11/I8 -> 0.22509439 | J12: =J11/J8 -> 0.23678934 | ... V12: =V11/V8 -> 0.24
B14: Less: SG&A Expenses | C14: ='Historical Data'!C14 -> 1050.58 | D14: ='Historical Data'!D14 -> 918.1 | E14: ='Historical Data'!E14 -> 957.12 | F14: ='Historical Data'!F14 -> 1059.3 | G14: ='Historical Data'!G14 -> 752.43 | H14: ='Historical Data'!H14 -> 984.43 | I14: ='Historical Data'!I14 -> 1302.87 | J14: ='Historical Data'!J14 -> 1628.45 | ... L14: ='Historical Data'!L14 -> 1929.5 | M14: =Schedule!E29 -> 2242.2798 | N14: =Schedule!F29 -> 2531.2847 | O14: =Schedule!G29 -> 2854.7267 | P14: =Schedule!H29 -> 3216.3254 | Q14: =Schedule!I29 -> 3620.1529 | R14: =Schedule!J29 -> 4070.6608 | S14: =Schedule!K29 -> 4572.709 | T14: =Schedule!L29 -> 5131.5957 | ... V14: =Schedule!N29 -> 6443.4596
B15: SG&A % Revenue | C15: =C14/C8 -> 0.23957184 | D15: =D14/D8 -> 0.19791117 | E15: =E14/E8 -> 0.18283653 | F15: =F14/F8 -> 0.19762359 | G15: =G14/G8 -> 0.17647804 | H15: =H14/H8 -> 0.16283467 | I15: =I14/I8 -> 0.16332177 | J15: =J14/J8 -> 0.16813521 | ... P15: =P14/P8 -> 0.16 | Q15: =Schedule!I31 -> 0.16 | R15: =Schedule!J31 -> 0.16 | S15: =Schedule!K31 -> 0.16 | T15: =Schedule!L31 -> 0.16 | U15: =Schedule!M31 -> 0.16 | V15: =Schedule!N31 -> 0.16
B16: Earning before Interest Taxes Depreciation & Amortization (EBITDA) | C16: =C11-C14 -> 222.41 | D16: =D11-D14 -> 265.9 | E16: =E11-E14 -> 346.54 | F16: =F11-F14 -> 282.78 | G16: =G11-G14 -> 239.81 | H16: =H11-H14 -> 346.47 | I16: =I11-I14 -> 492.78 | J16: =J11-J14 -> 664.94 | ... V16: =V11-V14 -> 3221.7298
B17: EBITDA Margin (%) | C17: =C16/C8 -> 0.050717863 | D17: =D16/D8 -> 0.057319005 | E17: =E16/E8 -> 0.066198776 | F17: =F16/F8 -> 0.052755593 | G17: =G16/G8 -> 0.056246027 | H17: =H16/H8 -> 0.057309638 | I17: =I16/I8 -> 0.061772625 | J17: =J16/J8 -> 0.068654134 | ... V17: =V16/V8 -> 0.08
B19: Less: Depreciation and Amortization | C19: ='Historical Data'!C19 -> 60.58 | D19: ='Historical Data'!D19 -> 63.81 | E19: ='Historical Data'!E19 -> 74.9 | F19: ='Historical Data'!F19 -> 87.99 | G19: ='Historical Data'!G19 -> 92.29 | H19: ='Historical Data'!H19 -> 85.98 | I19: ='Historical Data'!I19 -> 84.78 | J19: ='Historical Data'!J19 -> 97.61 | ... L19: ='Historical Data'!L19 -> 178.79 | M19: =Schedule!E128 -> 196.19948 | N19: =Schedule!F128 -> 221.48742 | O19: =Schedule!G128 -> 249.78858 | P19: =Schedule!H128 -> 281.42847 | Q19: =Schedule!I128 -> 316.76338 | R19: =Schedule!J128 -> 356.18282 | S19: =Schedule!K128 -> 400.11204 | T19: =Schedule!L128 -> 449.01462 | ... V19: =Schedule!N128 -> 563.80271
B20: Earning before Interest & Taxes (EBIT) | C20: =C16-C19 -> 161.83 | D20: =D16-D19 -> 202.09 | E20: =E16-E19 -> 271.64 | F20: =F16-F19 -> 194.79 | G20: =G16-G19 -> 147.52 | H20: =H16-H19 -> 260.49 | I20: =I16-I19 -> 408 | J20: =J16-J19 -> 567.33 | ... V20: =V16-V19 -> 2657.9271
B21: EBIT Margin (%) | C21: =C20/C8 -> 0.036903339 | D21: =D20/D8 -> 0.043563737 | E21: =E20/E8 -> 0.051890793 | F21: =F20/F8 -> 0.03634013 | G21: =G20/G8 -> 0.03459995 | H21: =H20/H8 -> 0.043087677 | I21: =I20/I8 -> 0.051144996 | J21: =J20/J8 -> 0.058576036 | ... V21: =V20/V8 -> 0.066
B23: Other Income | C23: ='Historical Data'!C23 -> 13.07 | D23: ='Historical Data'!D23 -> 16.95 | E23: ='Historical Data'!E23 -> 24.69 | F23: ='Historical Data'!F23 -> 44.7 | G23: ='Historical Data'!G23 -> 62.35 | H23: ='Historical Data'!H23 -> 35.72 | I23: ='Historical Data'!I23 -> 30.87 | J23: ='Historical Data'!J23 -> 47.42 | ... L23: ='Historical Data'!L23 -> 61.91 | M23: =Schedule!E205 -> 70.071243 | N23: =Schedule!F205 -> 79.102648 | O23: =Schedule!G205 -> 89.210209 | P23: =Schedule!H205 -> 100.51017 | Q23: =Schedule!I205 -> 113.12978 | R23: =Schedule!J205 -> 127.20815 | S23: =Schedule!K205 -> 142.89716 | T23: =Schedule!L205 -> 160.36236 | ... V23: =Schedule!N205 -> 201.35811
B24: Less: Interest Expenses | C24: ='Historical Data'!C24 -> 16.27 | D24: ='Historical Data'!D24 -> 28.74 | E24: ='Historical Data'!E24 -> 47.87 | F24: ='Historical Data'!F24 -> 29.47 | G24: ='Historical Data'!G24 -> 64.72 | H24: ='Historical Data'!H24 -> 46.4 | I24: ='Historical Data'!I24 -> 54.7 | J24: ='Historical Data'!J24 -> 58.08 | ... L24: ='Historical Data'!L24 -> 72.14 | M24: =Schedule!E200 -> 75.446471 | N24: =Schedule!F200 -> 80.553902 | O24: =Schedule!G200 -> 90.888943 | P24: =Schedule!H200 -> 102.449 | Q24: =Schedule!I200 -> 115.36557 | R24: =Schedule!J200 -> 129.78248 | S24: =Schedule!K200 -> 145.85687 | T24: =Schedule!L200 -> 163.76014 | ... V24: =Schedule!N200 -> 205.81676
B25: Less: Other Expense | C25: ='Historical Data'!C25 -> 0 | D25: ='Historical Data'!D25 -> -5.27 | E25: ='Historical Data'!E25 -> -2.68 | F25: ='Historical Data'!F25 -> 4.03 | G25: ='Historical Data'!G25 -> 0 | H25: ='Historical Data'!H25 -> 0 | I25: ='Historical Data'!I25 -> -170.81 | J25: ='Historical Data'!J25 -> 0 | ... L25: ='Historical Data'!L25 -> 38.83 | M25: =Schedule!E210 -> 0 | N25: =Schedule!F210 -> 0 | O25: =Schedule!G210 -> 0 | P25: =Schedule!H210 -> 0 | Q25: =Schedule!I210 -> 0 | R25: =Schedule!J210 -> 0 | S25: =Schedule!K210 -> 0 | T25: =Schedule!L210 -> 0 | ... V25: =Schedule!N210 -> 0
B26: Profit Before Tax (PBT) | C26: =C20+C23-C24-C25 -> 158.63 | D26: =D20+D23-D24-D25 -> 195.57 | E26: =E20+E23-E24-E25 -> 251.14 | F26: =F20+F23-F24-F25 -> 205.99 | G26: =G20+G23-G24-G25 -> 145.15 | H26: =H20+H23-H24-H25 -> 249.81 | I26: =I20+I23-I24-I25 -> 554.98 | J26: =J20+J23-J24-J25 -> 556.67 | ... V26: =V20+V23-V24-V25 -> 2653.4684
B27: EBT Margin (%) | C27: =C26/C8 -> 0.036173619 | D27: =D26/D8 -> 0.042158247 | E27: =E26/E8 -> 0.047974723 | F27: =F26/F8 -> 0.038429608 | G27: =G26/G8 -> 0.03404408 | H27: =H26/H8 -> 0.041321097 | I27: =I26/I8 -> 0.06956973 | J27: =J26/J8 -> 0.057475406 | ... V27: =V26/V8 -> 0.065889286
B29: Less: Tax Expense | C29: ='Historical Data'!C29 -> 36.67 | D29: ='Historical Data'!D29 -> 49.42 | E29: ='Historical Data'!E29 -> 41.99 | F29: ='Historical Data'!F29 -> 65.32 | G29: ='Historical Data'!G29 -> 47.09 | H29: ='Historical Data'!H29 -> 82.9 | I29: ='Historical Data'!I29 -> 154.69 | J29: ='Historical Data'!J29 -> 142.85 | ... L29: ='Historical Data'!L29 -> 175.78 | M29: =Schedule!E221 -> 229.8913 | N29: =Schedule!F221 -> 260.67593 | O29: =Schedule!G221 -> 293.97401 | P29: =Schedule!H221 -> 331.19885 | Q29: =Schedule!I221 -> 372.76932 | R29: =Schedule!J221 -> 419.14332 | S29: =Schedule!K221 -> 470.82069 | T29: =Schedule!L221 -> 528.34636 | ... V29: =Schedule!N221 -> 663.36711
B30: Net Income | C30: =C26-C29 -> 121.96 | D30: =D26-D29 -> 146.15 | E30: =E26-E29 -> 209.15 | F30: =F26-F29 -> 140.67 | G30: =G26-G29 -> 98.06 | H30: =H26-H29 -> 166.91 | I30: =I26-I29 -> 400.29 | J30: =J26-J29 -> 413.82 | ... V30: =V26-V29 -> 1990.1013
B31: Net Income Margin (%) | C31: =C30/C8 -> 0.027811477 | D31: =D30/D8 -> 0.031504974 | E31: =E30/E8 -> 0.039953466 | F31: =F30/F8 -> 0.026243473 | G31: =G30/G8 -> 0.022999397 | H31: =H30/H8 -> 0.0276086 | I31: =I30/I8 -> 0.050178506 | J31: =J30/J8 -> 0.042726342 | ... V31: =V30/V8 -> 0.049416964
